Workbook

Sheet Demand
A1: SportB – Demand Data per Region (in units)
A3: DEMAND BY STATE
A4: Region | B4: State | C4: Demand 2024 | D4: Demand 2025 | E4: Demand 2026 | F4: Demand 2027 | G4: Demand 2028 | H4: Demand 2029 | I4: Demand 2030
A5: West | B5: WA | C5: 50000 | D5: =C5*1.8 -> 90000 | E5: =D5*1.8 -> 162000 | F5: =E5*1.8 -> 291600 | G5: =F5 -> 291600 | H5: =G5 -> 291600 | I5: =H5 -> 291600
A6: West | B6: OR | C6: 20000 | D6: =C6*1.8 -> 36000 | E6: =D6*1.8 -> 64800 | F6: =E6*1.8 -> 116640 | G6: =F6 -> 116640 | H6: =G6 -> 116640 | I6: =H6 -> 116640
A7: West | B7: ID | C7: 10000 | D7: =C7*1.8 -> 18000 | E7: =D7*1.8 -> 32400 | F7: =E7*1.8 -> 58320 | G7: =F7 -> 58320 | H7: =G7 -> 58320 | I7: =H7 -> 58320
A8: West | B8: NV | C8: 60000 | D8: =C8*1.8 -> 108000 | E8: =D8*1.8 -> 194400 | F8: =E8*1.8 -> 349920 | G8: =F8 -> 349920 | H8: =G8 -> 349920 | I8: =H8 -> 349920
A9: West | B9: CA | C9: 80000 | D9: =C9*1.8 -> 144000 | E9: =D9*1.8 -> 259200 | F9: =E9*1.8 -> 466560 | G9: =F9 -> 466560 | H9: =G9 -> 466560 | I9: =H9 -> 466560
A10: West | B10: AZ | C10: 75000 | D10: =C10*1.8 -> 135000 | E10: =D10*1.8 -> 243000 | F10: =E10*1.8 -> 437400 | G10: =F10 -> 437400 | H10: =G10 -> 437400 | I10: =H10 -> 437400
A11: West | B11: UT | C11: 25000 | D11: =C11*1.8 -> 45000 | E11: =D11*1.8 -> 81000 | F11: =E11*1.8 -> 145800 | G11: =F11 -> 145800 | H11: =G11 -> 145800 | I11: =H11 -> 145800
A12: Southwest | B12: LA | C12: 10000 | D12: =C12*1.8 -> 18000 | E12: =D12*1.8 -> 32400 | F12: =E12*1.8 -> 58320 | G12: =F12 -> 58320 | H12: =G12 -> 58320 | I12: =H12 -> 58320
A13: Southwest | B13: TX | C13: 80000 | D13: =C13*1.8 -> 144000 | E13: =D13*1.8 -> 259200 | F13: =E13*1.8 -> 466560 | G13: =F13 -> 466560 | H13: =G13 -> 466560 | I13: =H13 -> 466560
A14: Southwest | B14: NM | C14: 60000 | D14: =C14*1.8 -> 108000 | E14: =D14*1.8 -> 194400 | F14: =E14*1.8 -> 349920 | G14: =F14 -> 349920 | H14: =G14 -> 349920 | I14: =H14 -> 349920
A15: Southwest | B15: OK | C15: 15000 | D15: =C15*1.8 -> 27000 | E15: =D15*1.8 -> 48600 | F15: =E15*1.8 -> 87480 | G15: =F15 -> 87480 | H15: =G15 -> 87480 | I15: =H15 -> 87480
A16: Southwest | B16: AR | C16: 35000 | D16: =C16*1.8 -> 63000 | E16: =D16*1.8 -> 113400 | F16: =E16*1.8 -> 204120 | G16: =F16 -> 204120 | H16: =G16 -> 204120 | I16: =H16 -> 204120
... A52: Southeast | B52: FL | C52: 45000 | D52: =C52*1.8 -> 81000 | E52: =D52*1.8 -> 145800 | F52: =E52*1.8 -> 262440 | G52: =F52 -> 262440 | H52: =G52 -> 262440 | I52: =H52 -> 262440
A60: DEMAND SUMMARY BY REGION & YEAR (units)
A61: Region | B61: 2024 | C61: 2025 | D61: 2026 | E61: 2027 | F61: Total 25-27 | G61: demand 2027 (next day)
A62: West | B62: =SUMIF(A5:A52,A62,C5:C52) -> 320000 | C62: =B62*(1+Parameters!B4) -> 576000 | D62: =C62*(1+Parameters!B4) -> 1036800 | E62: =D62*(1+Parameters!B4) -> 1866240 | F62: =C62+D62+E62 -> 3479040 | G62: =E62*1.1 -> 2052864
A63: Southwest | B63: =SUMIF(A5:A52,A63,C5:C52) -> 200000 | C63: =B63*(1+Parameters!B4) -> 360000 | D63: =C63*(1+Parameters!B4) -> 648000 | E63: =D63*(1+Parameters!B4) -> 1166400 | F63: =C63+D63+E63 -> 2174400 | G63: =E63*1.1 -> 1283040
A64: Northwest | B64: =SUMIF(A5:A52,A64,C5:C52) -> 160000 | C64: =B64*(1+Parameters!B4) -> 288000 | D64: =C64*(1+Parameters!B4) -> 518400 | E64: =D64*(1+Parameters!B4) -> 933120 | F64: =C64+D64+E64 -> 1739520 | G64: =E64*1.1 -> 1026432
A65: Midwest | B65: =SUMIF(A5:A52,A65,C5:C52) -> 220000 | C65: =B65*(1+Parameters!B4) -> 396000 | D65: =C65*(1+Parameters!B4) -> 712800 | E65: =D65*(1+Parameters!B4) -> 1283040 | F65: =C65+D65+E65 -> 2391840 | G65: =E65*1.1 -> 1411344
A66: Northeast | B66: =SUMIF(A5:A52,A66,C5:C52) -> 350000 | C66: =B66*(1+Parameters!B4) -> 630000 | D66: =C66*(1+Parameters!B4) -> 1134000 | E66: =D66*(1+Parameters!B4) -> 2041200 | F66: =C66+D66+E66 -> 3805200 | G66: =E66*1.1 -> 2245320
A67: Southeast | B67: =SUMIF(A5:A52,A67,C5:C52) -> 175000 | C67: =B67*(1+Parameters!B4) -> 315000 | D67: =C67*(1+Parameters!B4) -> 567000 | E67: =D67*(1+Parameters!B4) -> 1020600 | F67: =C67+D67+E67 -> 1902600 | G67: =E67*1.1 -> 1122660
A68: TOTAL | B68: =SUM(B62:B67) -> 1425000 | C68: =SUM(C62:C67) -> 2565000 | D68: =SUM(D62:D67) -> 4617000 | E68: =SUM(E62:E67) -> 8310600 | F68: =SUM(F62:F67) -> 15492600 | G68: =SUM(G62:G67) -> 9141660
A70: Number of Shipment SUMMARY BY REGION & YEAR (orders = units / 4)
A71: Region | B71: 2024 | C71: 2025 | D71: 2026 | E71: 2027 | F71: Total 25-27 | G71: demand 2027 (next day)
A72: West | B72: =B62/Parameters!$B$5 -> 80000 | C72: =C62/Parameters!$B$5 -> 144000 | D72: =D62/Parameters!$B$5 -> 259200 | E72: =E62/Parameters!$B$5 -> 466560 | F72: =F62/Parameters!$B$5 -> 869760 | G72: =E72*1.1 -> 513216
A73: Southwest | B73: =B63/Parameters!$B$5 -> 50000 | C73: =C63/Parameters!$B$5 -> 90000 | D73: =D63/Parameters!$B$5 -> 162000 | E73: =E63/Parameters!$B$5 -> 291600 | F73: =F63/Parameters!$B$5 -> 543600 | G73: =E73*1.1 -> 320760
A74: Northwest | B74: =B64/Parameters!$B$5 -> 40000 | C74: =C64/Parameters!$B$5 -> 72000 | D74: =D64/Parameters!$B$5 -> 129600 | E74: =E64/Parameters!$B$5 -> 233280 | F74: =F64/Parameters!$B$5 -> 434880 | G74: =E74*1.1 -> 256608
A75: Midwest | B75: =B65/Parameters!$B$5 -> 55000 | C75: =C65/Parameters!$B$5 -> 99000 | D75: =D65/Parameters!$B$5 -> 178200 | E75: =E65/Parameters!$B$5 -> 320760 | F75: =F65/Parameters!$B$5 -> 597960 | G75: =E75*1.1 -> 352836
A76: Northeast | B76: =B66/Parameters!$B$5 -> 87500 | C76: =C66/Parameters!$B$5 -> 157500 | D76: =D66/Parameters!$B$5 -> 283500 | E76: =E66/Parameters!$B$5 -> 510300 | F76: =F66/Parameters!$B$5 -> 951300 | G76: =E76*1.1 -> 561330
A77: Southeast | B77: =B67/Parameters!$B$5 -> 43750 | C77: =C67/Parameters!$B$5 -> 78750 | D77: =D67/Parameters!$B$5 -> 141750 | E77: =E67/Parameters!$B$5 -> 255150 | F77: =F67/Parameters!$B$5 -> 475650 | G77: =E77*1.1 -> 280665
A78: TOTAL | B78: =SUM(B72:B77) -> 356250 | C78: =SUM(C72:C77) -> 641250 | D78: =SUM(D72:D77) -> 1154250 | E78: =SUM(E72:E77) -> 2077650 | F78: =SUM(F72:F77) -> 3873150 | G78: =SUM(G72:G77) -> 2285415

Sheet __OpenSolverCache__

Sheet __OpenSolver__
A1: =ModelSheet=Q5_Model_international!A:Z -> #NAME? | B1: =ModelSheet=Q2_Model_Baseline!A:Z -> #NAME?
A2: =OpenSolver_AdjNum=5 -> #NAME? | B2: =OpenSolver_AdjNum=6 -> #NAME?
A3: =OpenSolver_ChosenSolver=NeosCBC -> #NAME? | B3: =OpenSolver_ChosenSolver=NeosCBC -> #NAME?
A4: =OpenSolver_FastBuild=0 -> #NAME? | B4: =OpenSolver_FastBuild=0 -> #NAME?
A5: =OpenSolver_LinearityCheck=1 -> #NAME? | B5: =OpenSolver_LinearityCheck=1 -> #NAME?
A6: =solver_adj=Q5_Model_international!C7:E16 -> #NAME? | B6: =solver_adj=Q2_Model_Baseline!B21:G25 -> #NAME?
A7: =solver_adj1=Q5_Model_international!B21:G35 -> #NAME? | B7: =solver_adj1=Q2_Model_Baseline!B26:G30 -> #NAME?
A8: =solver_adj2=Q5_Model_international!B39:D48 -> #NAME? | B8: =solver_adj2=Q2_Model_Baseline!B31:G35 -> #NAME?
A9: =solver_adj3=Q5_Model_international!B52:D54 -> #NAME? | B9: =solver_adj3=Q2_Model_Baseline!B51:F53 -> #NAME?
A10: =solver_adj4=Q5_Model_international!B58:F66 -> #NAME? | B10: =solver_adj4=Q2_Model_Baseline!C7:E16 -> #NAME?
A11: =solver_lhs1=Q5_Model_international!C7:E16 -> #NAME? | B11: =solver_adj5=Q2_Model_Baseline!B39:D48 -> #NAME?
A12: =solver_lhs2=Q5_Model_international!B52:D54 -> #NAME? | B12: =solver_lhs1=Q2_Model_Baseline!B61:D66 -> #NAME?
A13: =solver_lhs3=Q5_Model_international!B72:D77 -> #NAME? | B13: =solver_lhs2=Q2_Model_Baseline!B70:D74 -> #NAME?
A14: =solver_lhs4=Q5_Model_international!B81:D85 -> #NAME? | B14: =solver_lhs3=Q2_Model_Baseline!B78:D82 -> #NAME?
A15: =solver_lhs5=Q5_Model_international!B89:D93 -> #NAME? | B15: =solver_lhs4=Q2_Model_Baseline!B87:D96 -> #NAME?
A16: =solver_lhs6=Q5_Model_international!B98:D107 -> #NAME? | B16: =solver_lhs5=Q2_Model_Baseline!B100:D100 -> #NAME?
A17: =solver_lhs7=Q5_Model_international!B111:D113 -> #NAME? | B17: =solver_lhs6=Q2_Model_Baseline!B104:D108 -> #NAME?
A18: =solver_lhs8=Q5_Model_international!B117:D121 -> #NAME? | B18: =solver_neg=1 -> #NAME?
A19: =solver_neg=1 -> #NAME? | B19: =solver_num=6 -> #NAME?
A20: =solver_num=8 -> #NAME? | B20: =solver_opt=Q2_Model_Baseline!E124 -> #NAME?
A21: =solver_opt=Q5_Model_international!E135 -> #NAME? | B21: =solver_rel1=2 -> #NAME?
A22: =solver_rel1=5 -> #NAME? | B22: =solver_rel2=1 -> #NAME?
A23: =solver_rel2=5 -> #NAME? | B23: =solver_rel3=1 -> #NAME?
A24: =solver_rel3=2 -> #NAME? | B24: =solver_rel4=1 -> #NAME?
A25: =solver_rel4=1 -> #NAME? | B25: =solver_rel5=1 -> #NAME?
A26: =solver_rel5=1 -> #NAME? | B26: =solver_rel6=2 -> #NAME?
A27: =solver_rel6=1 -> #NAME? | B27: =solver_rhs1=Q2_Model_Baseline!E61:G66 -> #NAME?
A28: =solver_rel7=1 -> #NAME? | B28: =solver_rhs2=Q2_Model_Baseline!E70:G74 -> #NAME?
A29: =solver_rel8=2 -> #NAME? | B29: =_xlfn.SINGLE(solver_rhs3)=_xlfn.SINGLE(Q2_Model_Baseline!#REF!) -> #NAME?
A30: =solver_rhs1=binary -> #NAME? | B30: =solver_rhs4=Q2_Model_Baseline!B39:D48 -> #NAME?
A31: =solver_rhs2=binary -> #NAME? | B31: =solver_rhs5=Q2_Model_Baseline!E100:G100 -> #NAME?
A32: =solver_rhs3=Q5_Model_international!E72:G77 -> #NAME? | B32: =solver_rhs6=Q2_Model_Baseline!E104:G108 -> #NAME?
A33: =solver_rhs4=Q5_Model_international!E81:G85 -> #NAME? | B33: =solver_sho=1 -> #NAME?
A34: =solver_rhs5=Q5_Model_international!I89:K93 -> #NAME? | B34: =solver_typ=2 -> #NAME?
A35: =solver_rhs6=Q5_Model_international!B39:D48 -> #NAME? | B35: =solver_val=0 -> #NAME?
A36: =solver_rhs7=Q5_Model_international!E111:G113 -> #NAME?
A37: =solver_rhs8=Q5_Model_international!E117:G121 -> #NAME?
A38: =solver_sho=1 -> #NAME?
A39: =solver_typ=2 -> #NAME?
A40: =solver_val=0 -> #NAME?

Sheet Parameters
A1: SportB – Model Parameters (2025–2027)
A3: GENERAL ASSUMPTIONS
A4: Demand growth rate / year | B4: 0.8
A5: Avg units per order | B5: 4 | D5: Q6_Insourcing
A6: Avg selling price ($/unit) | B6: 14 | D6: in sourcing share | E6: =0.8 -> 0.8
A7: Avg purchase price US ($/unit) | B7: 10 | C7: ? | D7: in soucing cost | E7: 8
A8: WH transfer/close cost ($) | B8: 30000 | D8: new product share | E8: 0.2
A9: WH holding cost – fixed ($) | B9: 475000 | D9: new product unit | E9: 10
A10: WH holding cost – variable ($/unit) | B10: 0.165 | D10: blended | E10: =E6*E7+E8*E9 -> 8.4
A11: Years in planning horizon | B11: 3
A12: Local supplier max capacity (units/year) | B12: 17000000
A13: small | B13: 10000 m^2
A14: large | B14: 20000 m^2
A18: WAREHOUSE DATA
A19: Location | B19: Small FC ($/yr) | C19: Small VC ($/unit) | D19: Small Cap (M units) | E19: Large FC ($/yr) | F19: Large VC ($/unit) | G19: Large Cap (M units)
A20: Seattle | B20: 300000 | C20: 0.2 | D20: 2000000 | E20: 500000 | F20: 0.2 | G20: 4000000
A21: Denver | B21: 250000 | C21: 0.2 | D21: 2000000 | E21: 420000 | F21: 0.2 | G21: 4000000
A22: Saint-Louis | B22: 220000 | C22: 0.2 | D22: 2000000 | E22: 375000 | F22: 0.2 | G22: 4000000
A23: Atlanta | B23: 220000 | C23: 0.2 | D23: 2000000 | E23: 375000 | F23: 0.2 | G23: 4000000
A24: Philadelphia | B24: 240000 | C24: 0.2 | D24: 2000000 | E24: 400000 | F24: 0.2 | G24: 4000000
A26: UPS OUTBOUND RATES ($/shipment of 4 units, WH → Region)
A27: WH \ Region | B27: West | C27: Southwest | D27: Northwest | E27: Midwest | F27: Northeast | G27: Southeast
A28: Seattle | B28: 2 | C28: 2.5 | D28: 3.5 | E28: 4 | F28: 5 | G28: 5.5
A29: Denver | B29: 2.5 | C29: 2.5 | D29: 2.5 | E29: 3 | F29: 4 | G29: 4.5
A30: Saint-Louis | B30: 3 | C30: 3 | D30: 2.5 | E30: 2.5 | F30: 3 | G30: 3.5
A31: Atlanta | B31: 4 | C31: 4 | D31: 3 | E31: 2.5 | F31: 3 | G31: 2.5
A32: Philadelphia | B32: 4.5 | C32: 5 | D32: 3 | E32: 3.5 | F32: 2.5 | G32: 4
A34: SUPPLY DATA (annual contract)
A35: Source | B35: Fixed Cost ($/yr) | C35: Variable Cost ($/unit) | D35: Annual Capacity (M units)
A36: Suzhou (China) | B36: 10000 | C36: 0.1 | D36: 3000000
A37: Juarez (Mexico) | B37: 30000 | C37: 0.2 | D37: 6000000
A38: US Sources | B38: 20000 | C38: 0.3 | D38: 17000000
A40: UPS INBOUND RATES ($/shipment of 4 units, Source → WH)
A41: WH \ Source | B41: Suzhou | C41: Juarez | D41: US Sources
A42: Seattle | B42: 5 | C42: 1.5 | D42: 3.5
A43: Denver | B43: 5.5 | C43: 3.5 | D43: 2.5
A44: Saint-Louis | B44: 7 | C44: 5 | D44: 2.5
A45: Atlanta | B45: 7 | C45: 5 | D45: 3
A46: Philadelphia | B46: 8 | C46: 6 | D46: 3
A51: Inbound costs (detail) | B51: Seattle | C51: Denver | D51: Saint-Louis | E51: Atlanta | F51: Philadelphia | G51: Total orders | H51: Year
...

Sheet Q1_ST_Louis only
A1: SportB – MIP Model: Saint-Louis Only
A4: SECTION 1 – DECISION VARIABLES
A5: y(w,s,t) = 1 if warehouse w is open at size s (S=small, L=large) in year t [Binary]
A6: Variable y(w,s,t) | B6: 2024 | C6: 2025 | D6: 2026 | E6: 2027
A7: y(SEA,S) | B7: 0 | C7: 0 | D7: 0.3085 | E7: 0
A8: y(SEA,L) | B8: 0 | C8: 0 | D8: 0 | E8: 0
A9: y(DEN,S) | B9: 0 | C9: 0 | D9: 0 | E9: 0
A10: y(DEN,L) | B10: 0 | C10: 0 | D10: 0 | E10: 0
A11: y(STL,S) | B11: 1 | C11: 0 | D11: 0 | E11: 0
A12: y(STL,L) | B12: 0 | C12: 1 | D12: 1 | E12: 1
A13: y(ATL,S) | B13: 0 | C13: 0 | D13: 0 | E13: 2.1553
A14: y(ATL,L) | B14: 0 | C14: 0 | D14: 0 | E14: 0
A15: y(PHL,S) | B15: 0 | C15: 0 | D15: 0 | E15: 0
A16: y(PHL,L) | B16: 0 | C16: 0 | D16: 0 | E16: 0
A19: x(w,reg,t) = # orders shipped from warehouse w to region reg in year t [Continuous ≥ 0]
A20: x(w,reg) → | B20: West | C20: Southw | D20: Northw | E20: Midwes | F20: Northe | G20: Southe | H20: Total orders | I20: Year
A21: x(SEA,2025) | B21: 0 | C21: 0 | D21: 0 | E21: 0 | F21: 0 | G21: 0 | H21: =SUM(B21:G21) -> 0 | I21: 2025
A22: x(DEN,2025) | B22: 0 | C22: 0 | D22: 0 | E22: 0 | F22: 0 | G22: 0 | H22: =SUM(B22:G22) -> 0 | I22: 2025
A23: x(STL,2025) | B23: 144000 | C23: 90000 | D23: 72000 | E23: 99000 | F23: 157500 | G23: 78750 | H23: =SUM(B23:G23) -> 641250 | I23: 2025
A24: x(ATL,2025) | B24: 0 | C24: 0 | D24: 0 | E24: 0 | F24: 0 | G24: 0 | H24: =SUM(B24:G24) -> 0 | I24: 2025
A25: x(PHL,2025) | B25: 0 | C25: 0 | D25: 0 | E25: 0 | F25: 0 | G25: 0 | H25: =SUM(B25:G25) -> 0 | I25: 2025
A26: x(SEA,2026) | B26: 154250 | C26: 0 | D26: 0 | E26: 0 | F26: 0 | G26: 0 | H26: =SUM(B26:G26) -> 154250 | I26: 2026
A27: x(DEN,2026) | B27: 0 | C27: 0 | D27: 0 | E27: 0 | F27: 0 | G27: 0 | H27: =SUM(B27:G27) -> 0 | I27: 2026
A28: x(STL,2026) | B28: 104950 | C28: 162000 | D28: 129600 | E28: 178200 | F28: 283500 | G28: 141750 | H28: =SUM(B28:G28) -> 1000000 | I28: 2026
A29: x(ATL,2026) | B29: 0 | C29: 0 | D29: 0 | E29: 0 | F29: 0 | G29: 0 | H29: =SUM(B29:G29) -> 0 | I29: 2026
A30: x(PHL,2026) | B30: 0 | C30: 0 | D30: 0 | E30: 0 | F30: 0 | G30: 0 | H30: =SUM(B30:G30) -> 0 | I30: 2026
A31: x(SEA,2027) | B31: 0 | C31: 0 | D31: 0 | E31: 0 | F31: 0 | G31: 0 | H31: =SUM(B31:G31) -> 0 | I31: 2027
A32: x(DEN,2027) | B32: 0 | C32: 0 | D32: 0 | E32: 0 | F32: 0 | G32: 0 | H32: =SUM(B32:G32) -> 0 | I32: 2027
... A35: x(PHL,2027) | B35: 0 | C35: 0 | D35: 0 | E35: 0 | F35: 0 | G35: 0 | H35: =SUM(B35:G35) -> 0 | I35: 2027
A38: Tranfer ? | B38: 2025 | C38: 2026 | D38: 2027
A39: y(SEA,S) | B39: 0 | C39: 0 | D39: 0.3085
A40: y(SEA,L) | B40: 0 | C40: 0 | D40: 0
A41: y(DEN,S) | B41: 0 | C41: 0 | D41: 0
A42: y(DEN,L) | B42: 0 | C42: 0 | D42: 0
A43: y(STL,S) | B43: 1 | C43: 0 | D43: 0
A44: y(STL,L) | B44: 0 | C44: 0 | D44: 0
A45: y(ATL,S) | B45: 0 | C45: 0 | D45: 0
A46: y(ATL,L) | B46: 0 | C46: 0 | D46: 0
A47: y(PHL,S) | B47: 0 | C47: 0 | D47: 0
A48: y(PHL,L) | B48: 0 | C48: 0 | D48: 0
...

Sheet Q2_Model_Baseline
A1: SportB – MIP Model: Baseline (Minimize Total Cost 2025–2027)
A4: SECTION 1 – DECISION VARIABLES
A5: y(w,s,t) = 1 if warehouse w is open at size s (S=small, L=large) in year t [Binary]
A6: Variable y(w,s,t) | B6: 2024 | C6: 2025 | D6: 2026 | E6: 2027
A7: y(SEA,S) | B7: 0 | C7: 0 | D7: 0 | E7: 0
A8: y(SEA,L) | B8: 0 | C8: 0 | D8: 0 | E8: 0
A9: y(DEN,S) | B9: 0 | C9: 0 | D9: 1 | E9: 0
A10: y(DEN,L) | B10: 0 | C10: 0 | D10: 0 | E10: 1
A11: y(STL,S) | B11: 1 | C11: 0 | D11: 0 | E11: 0
A12: y(STL,L) | B12: 0 | C12: 1 | D12: 1 | E12: 1
A13: y(ATL,S) | B13: 0 | C13: 0 | D13: 0 | E13: 1
A14: y(ATL,L) | B14: 0 | C14: 0 | D14: 0 | E14: 0
A15: y(PHL,S) | B15: 0 | C15: 0 | D15: 0 | E15: 0
A16: y(PHL,L) | B16: 0 | C16: 0 | D16: 0 | E16: 0
A19: x(w,reg,t) = # orders shipped from warehouse w to region reg in year t [Continuous ≥ 0]
A20: x(w,reg) → | B20: West | C20: Southw | D20: Northw | E20: Midwes | F20: Northe | G20: Southe | H20: Total orders | I20: Year
A21: x(SEA,2025) | B21: 0 | C21: 0 | D21: 0 | E21: 0 | F21: 0 | G21: 0 | H21: =SUM(B21:G21) -> 0 | I21: 2025
A22: x(DEN,2025) | B22: 0 | C22: 0 | D22: 0 | E22: 0 | F22: 0 | G22: 0 | H22: =SUM(B22:G22) -> 0 | I22: 2025
A23: x(STL,2025) | B23: 144000 | C23: 90000 | D23: 72000 | E23: 99000 | F23: 157500 | G23: 78750 | H23: =SUM(B23:G23) -> 641250 | I23: 2025
A24: x(ATL,2025) | B24: 0 | C24: 0 | D24: 0 | E24: 0 | F24: 0 | G24: 0 | H24: =SUM(B24:G24) -> 0 | I24: 2025
A25: x(PHL,2025) | B25: 0 | C25: 0 | D25: 0 | E25: 0 | F25: 0 | G25: 0 | H25: =SUM(B25:G25) -> 0 | I25: 2025
A26: x(SEA,2026) | B26: 0 | C26: 0 | D26: 0 | E26: 0 | F26: 0 | G26: 0 | H26: =SUM(B26:G26) -> 0 | I26: 2026
A27: x(DEN,2026) | B27: 259200 | C27: 162000 | D27: 0 | E27: 0 | F27: 0 | G27: 0 | H27: =SUM(B27:G27) -> 421200 | I27: 2026
A28: x(STL,2026) | B28: 0 | C28: 0 | D28: 129600 | E28: 178200 | F28: 283500 | G28: 141750 | H28: =SUM(B28:G28) -> 733050 | I28: 2026
A29: x(ATL,2026) | B29: 0 | C29: 0 | D29: 0 | E29: 0 | F29: 0 | G29: 0 | H29: =SUM(B29:G29) -> 0 | I29: 2026
A30: x(PHL,2026) | B30: 0 | C30: 0 | D30: 0 | E30: 0 | F30: 0 | G30: 0 | H30: =SUM(B30:G30) -> 0 | I30: 2026
A31: x(SEA,2027) | B31: 0 | C31: 0 | D31: 0 | E31: 0 | F31: 0 | G31: 0 | H31: =SUM(B31:G31) -> 0 | I31: 2027
A32: x(DEN,2027) | B32: 466560 | C32: 291600 | D32: 64340 | E32: 0 | F32: 0 | G32: 0 | H32: =SUM(B32:G32) -> 822500 | I32: 2027
... A35: x(PHL,2027) | B35: 0 | C35: 0 | D35: 0 | E35: 0 | F35: 0 | G35: 0 | H35: =SUM(B35:G35) -> 0 | I35: 2027
A38: Tranfer ? | B38: 2025 | C38: 2026 | D38: 2027
A39: y(SEA,S) | B39: 0 | C39: 0 | D39: 0
A40: y(SEA,L) | B40: 0 | C40: 0 | D40: 0
A41: y(DEN,S) | B41: 0 | C41: 0 | D41: 1
A42: y(DEN,L) | B42: 0 | C42: 0 | D42: 0
A43: y(STL,S) | B43: 1 | C43: 0 | D43: 0
A44: y(STL,L) | B44: 0 | C44: 0 | D44: 0
A45: y(ATL,S) | B45: 0 | C45: 0 | D45: 0
A46: y(ATL,L) | B46: 0 | C46: 0 | D46: 0
A47: y(PHL,S) | B47: 0 | C47: 0 | D47: 0
A48: y(PHL,L) | B48: 0 | C48: 0 | D48: 0
...

Sheet Q3_next_day 
A1: SportB – MIP Model: Next day delivery
A4: SECTION 1 – DECISION VARIABLES
A5: y(w,s,t) = 1 if warehouse w is open at size s (S=small, L=large) in year t [Binary]
A6: Variable y(w,s,t) | B6: 2024 | C6: 2025 | D6: 2026 | E6: 2027
A7: y(SEA,S) | B7: 0 | C7: 0 | D7: 0 | E7: 0
A8: y(SEA,L) | B8: 0 | C8: 0 | D8: 0 | E8: 0
A9: y(DEN,S) | B9: 0 | C9: 0 | D9: 1 | E9: 0
A10: y(DEN,L) | B10: 0 | C10: 0 | D10: 0 | E10: 1
A11: y(STL,S) | B11: 1 | C11: 0 | D11: 0 | E11: 0
A12: y(STL,L) | B12: 0 | C12: 1 | D12: 1 | E12: 1
A13: y(ATL,S) | B13: 0 | C13: 0 | D13: 0 | E13: 1
A14: y(ATL,L) | B14: 0 | C14: 0 | D14: 0 | E14: 0
A15: y(PHL,S) | B15: 0 | C15: 0 | D15: 0 | E15: 0
A16: y(PHL,L) | B16: 0 | C16: 0 | D16: 0 | E16: 0
A19: x(w,reg,t) = # orders shipped from warehouse w to region reg in year t [Continuous ≥ 0]
A20: x(w,reg) → | B20: West | C20: Southw | D20: Northw | E20: Midwes | F20: Northe | G20: Southe | H20: Total orders | I20: Year
A21: x(SEA,2025) | B21: 0 | C21: 0 | D21: 0 | E21: 0 | F21: 0 | G21: 0 | H21: =SUM(B21:G21) -> 0 | I21: 2025
A22: x(DEN,2025) | B22: 0 | C22: 0 | D22: 0 | E22: 0 | F22: 0 | G22: 0 | H22: =SUM(B22:G22) -> 0 | I22: 2025
A23: x(STL,2025) | B23: 144000 | C23: 90000 | D23: 72000 | E23: 99000 | F23: 157500 | G23: 78750 | H23: =SUM(B23:G23) -> 641250 | I23: 2025
A24: x(ATL,2025) | B24: 0 | C24: 0 | D24: 0 | E24: 0 | F24: 0 | G24: 0 | H24: =SUM(B24:G24) -> 0 | I24: 2025
A25: x(PHL,2025) | B25: 0 | C25: 0 | D25: 0 | E25: 0 | F25: 0 | G25: 0 | H25: =SUM(B25:G25) -> 0 | I25: 2025
A26: x(SEA,2026) | B26: 0 | C26: 0 | D26: 0 | E26: 0 | F26: 0 | G26: 0 | H26: =SUM(B26:G26) -> 0 | I26: 2026
A27: x(DEN,2026) | B27: 259200 | C27: 162000 | D27: 0 | E27: 0 | F27: 0 | G27: 0 | H27: =SUM(B27:G27) -> 421200 | I27: 2026
A28: x(STL,2026) | B28: 0 | C28: 0 | D28: 129600 | E28: 178200 | F28: 283500 | G28: 141750 | H28: =SUM(B28:G28) -> 733050 | I28: 2026
A29: x(ATL,2026) | B29: 0 | C29: 0 | D29: 0 | E29: 0 | F29: 0 | G29: 0 | H29: =SUM(B29:G29) -> 0 | I29: 2026
A30: x(PHL,2026) | B30: 0 | C30: 0 | D30: 0 | E30: 0 | F30: 0 | G30: 0 | H30: =SUM(B30:G30) -> 0 | I30: 2026
A31: x(SEA,2027) | B31: 0 | C31: 0 | D31: 0 | E31: 0 | F31: 0 | G31: 0 | H31: =SUM(B31:G31) -> 0 | I31: 2027
A32: x(DEN,2027) | B32: 513216 | C32: 320760 | D32: 166024 | E32: 0 | F32: 0 | G32: 0 | H32: =SUM(B32:G32) -> 1000000 | I32: 2027
... A35: x(PHL,2027) | B35: 0 | C35: 0 | D35: 0 | E35: 0 | F35: 0 | G35: 0 | H35: =SUM(B35:G35) -> 0 | I35: 2027
A38: Tranfer ? | B38: 2025 | C38: 2026 | D38: 2027
A39: y(SEA,S) | B39: 0 | C39: 0 | D39: 0 | F39: UPS OUTBOUND RATES ($/shipment of 4 units, WH → Region) - +20%
A40: y(SEA,L) | B40: 0 | C40: 0 | D40: 0 | F40: WH \ Region | G40: West | H40: Southwest | I40: Northwest | J40: Midwest | K40: Northeast | L40: Southeast
A41: y(DEN,S) | B41: 0 | C41: 0 | D41: 1 | F41: Seattle | G41: =Parameters!B28*1.2 -> 2.4 | H41: =Parameters!C28*1.2 -> 3 | I41: =Parameters!D28*1.2 -> 4.2 | J41: =Parameters!E28*1.2 -> 4.8 | K41: =Parameters!F28*1.2 -> 6 | L41: =Parameters!G28*1.2 -> 6.6
A42: y(DEN,L) | B42: 0 | C42: 0 | D42: 0 | F42: Denver | G42: =Parameters!B29*1.2 -> 3 | H42: =Parameters!C29*1.2 -> 3 | I42: =Parameters!D29*1.2 -> 3 | J42: =Parameters!E29*1.2 -> 3.6 | K42: =Parameters!F29*1.2 -> 4.8 | L42: =Parameters!G29*1.2 -> 5.4
A43: y(STL,S) | B43: 1 | C43: 0 | D43: 0 | F43: Saint-Louis | G43: =Parameters!B30*1.2 -> 3.6 | H43: =Parameters!C30*1.2 -> 3.6 | I43: =Parameters!D30*1.2 -> 3 | J43: =Parameters!E30*1.2 -> 3 | K43: =Parameters!F30*1.2 -> 3.6 | L43: =Parameters!G30*1.2 -> 4.2
A44: y(STL,L) | B44: 0 | C44: 0 | D44: 0 | F44: Atlanta | G44: =Parameters!B31*1.2 -> 4.8 | H44: =Parameters!C31*1.2 -> 4.8 | I44: =Parameters!D31*1.2 -> 3.6 | J44: =Parameters!E31*1.2 -> 3 | K44: =Parameters!F31*1.2 -> 3.6 | L44: =Parameters!G31*1.2 -> 3
A45: y(ATL,S) | B45: 0 | C45: 0 | D45: 0 | F45: Philadelphia | G45: =Parameters!B32*1.2 -> 5.4 | H45: =Parameters!C32*1.2 -> 6 | I45: =Parameters!D32*1.2 -> 3.6 | J45: =Parameters!E32*1.2 -> 4.2 | K45: =Parameters!F32*1.2 -> 3 | L45: =Parameters!G32*1.2 -> 4.8
A46: y(ATL,L) | B46: 0 | C46: 0 | D46: 0
A47: y(PHL,S) | B47: 0 | C47: 0 | D47: 0
A48: y(PHL,L) | B48: 0 | C48: 0 | D48: 0
...

Sheet Q4_Resillient
A1: SportB – MIP Model: Resilient
A4: SECTION 1 – DECISION VARIABLES
A5: y(w,s,t) = 1 if warehouse w is open at size s (S=small, L=large) in year t [Binary]
A6: Variable y(w,s,t) | B6: 2024 | C6: 2025 | D6: 2026 | E6: 2027
A7: y(SEA,S) | B7: 0 | C7: 0 | D7: 0 | E7: 0 | H7: Resilient WH | I7: 2025 | J7: 2026 | K7: 2027
A8: y(SEA,L) | B8: 0 | C8: 0 | D8: 0 | E8: 0 | I8: =SUM(C7:C16) -> 2 | J8: =SUM(D7:D16) -> 2 | K8: =SUM(E7:E16) -> 3
A9: y(DEN,S) | B9: 0 | C9: 0 | D9: 1 | E9: 0
A10: y(DEN,L) | B10: 0 | C10: 0 | D10: 0 | E10: 1
A11: y(STL,S) | B11: 1 | C11: 1 | D11: 0 | E11: 0
A12: y(STL,L) | B12: 0 | C12: 0 | D12: 1 | E12: 1
A13: y(ATL,S) | B13: 0 | C13: 1 | D13: 0 | E13: 1
A14: y(ATL,L) | B14: 0 | C14: 0 | D14: 0 | E14: 0
A15: y(PHL,S) | B15: 0 | C15: 0 | D15: 0 | E15: 0
A16: y(PHL,L) | B16: 0 | C16: 0 | D16: 0 | E16: 0
A19: x(w,reg,t) = # orders shipped from warehouse w to region reg in year t [Continuous ≥ 0]
A20: x(w,reg) → | B20: West | C20: Southw | D20: Northw | E20: Midwes | F20: Northe | G20: Southe | H20: Total orders | I20: Year
A21: x(SEA,2025) | B21: 0 | C21: 0 | D21: 0 | E21: 0 | F21: 0 | G21: 0 | H21: =SUM(B21:G21) -> 0 | I21: 2025
A22: x(DEN,2025) | B22: 0 | C22: 0 | D22: 0 | E22: 0 | F22: 0 | G22: 0 | H22: =SUM(B22:G22) -> 0 | I22: 2025
A23: x(STL,2025) | B23: 144000 | C23: 90000 | D23: 72000 | E23: 36500 | F23: 157500 | G23: 0 | H23: =SUM(B23:G23) -> 500000 | I23: 2025
A24: x(ATL,2025) | B24: 0 | C24: 0 | D24: 0 | E24: 62500 | F24: 0 | G24: 78750 | H24: =SUM(B24:G24) -> 141250 | I24: 2025
A25: x(PHL,2025) | B25: 0 | C25: 0 | D25: 0 | E25: 0 | F25: 0 | G25: 0 | H25: =SUM(B25:G25) -> 0 | I25: 2025
A26: x(SEA,2026) | B26: 0 | C26: 0 | D26: 0 | E26: 0 | F26: 0 | G26: 0 | H26: =SUM(B26:G26) -> 0 | I26: 2026
A27: x(DEN,2026) | B27: 259200 | C27: 162000 | D27: 0 | E27: 0 | F27: 0 | G27: 0 | H27: =SUM(B27:G27) -> 421200 | I27: 2026
A28: x(STL,2026) | B28: 0 | C28: 0 | D28: 129600 | E28: 178200 | F28: 283500 | G28: 141750 | H28: =SUM(B28:G28) -> 733050 | I28: 2026
A29: x(ATL,2026) | B29: 0 | C29: 0 | D29: 0 | E29: 0 | F29: 0 | G29: 0 | H29: =SUM(B29:G29) -> 0 | I29: 2026
A30: x(PHL,2026) | B30: 0 | C30: 0 | D30: 0 | E30: 0 | F30: 0 | G30: 0 | H30: =SUM(B30:G30) -> 0 | I30: 2026
A31: x(SEA,2027) | B31: 0 | C31: 0 | D31: 0 | E31: 0 | F31: 0 | G31: 0 | H31: =SUM(B31:G31) -> 0 | I31: 2027
A32: x(DEN,2027) | B32: 466560 | C32: 291600 | D32: 64340 | E32: 0 | F32: 0 | G32: 0 | H32: =SUM(B32:G32) -> 822500 | I32: 2027
... A35: x(PHL,2027) | B35: 0 | C35: 0 | D35: 0 | E35: 0 | F35: 0 | G35: 0 | H35: =SUM(B35:G35) -> 0 | I35: 2027
A38: Tranfer ? | B38: 2025 | C38: 2026 | D38: 2027
A39: y(SEA,S) | B39: 0 | C39: 0 | D39: 0
A40: y(SEA,L) | B40: 0 | C40: 0 | D40: 0
A41: y(DEN,S) | B41: 0 | C41: 0 | D41: 1
A42: y(DEN,L) | B42: 0 | C42: 0 | D42: 0
A43: y(STL,S) | B43: 0 | C43: 1 | D43: 0
A44: y(STL,L) | B44: 0 | C44: 0 | D44: 0
A45: y(ATL,S) | B45: 0 | C45: 1 | D45: 0
A46: y(ATL,L) | B46: 0 | C46: 0 | D46: 0
A47: y(PHL,S) | B47: 0 | C47: 0 | D47: 0
A48: y(PHL,L) | B48: 0 | C48: 0 | D48: 0
...

Sheet Q5_Model_international
A1: SportB – MIP Model: International
A4: SECTION 1 – DECISION VARIABLES
A5: y(w,s,t) = 1 if warehouse w is open at size s (S=small, L=large) in year t [Binary]
A6: Variable y(w,s,t) | B6: 2024 | C6: 2025 | D6: 2026 | E6: 2027
A7: y(SEA,S) | B7: 0 | C7: 0 | D7: 0 | E7: 0
A8: y(SEA,L) | B8: 0 | C8: 1 | D8: 1 | E8: 1
A9: y(DEN,S) | B9: 0 | C9: 0 | D9: 0 | E9: 0
A10: y(DEN,L) | B10: 0 | C10: 0 | D10: 0 | E10: 0
A11: y(STL,S) | B11: 1 | C11: 0 | D11: 1 | E11: 0
A12: y(STL,L) | B12: 0 | C12: 0 | D12: 0 | E12: 1
A13: y(ATL,S) | B13: 0 | C13: 0 | D13: 0 | E13: 1
A14: y(ATL,L) | B14: 0 | C14: 0 | D14: 0 | E14: 0
A15: y(PHL,S) | B15: 0 | C15: 0 | D15: 0 | E15: 0
A16: y(PHL,L) | B16: 0 | C16: 0 | D16: 0 | E16: 0
A19: x(w,reg,t) = # orders shipped from warehouse w to region reg in year t [Continuous ≥ 0]
A20: flux sortants (x(w,reg) ) | B20: West | C20: Southw | D20: Northw | E20: Midwes | F20: Northe | G20: Southe | H20: Total orders | I20: Year
A21: x(SEA,2025) | B21: 144000 | C21: 90000 | D21: 72000 | E21: 99000 | F21: 157500 | G21: 78750 | H21: =SUM(B21:G21) -> 641250 | I21: 2025
A22: x(DEN,2025) | B22: 0 | C22: 0 | D22: 0 | E22: 0 | F22: 0 | G22: 0 | H22: =SUM(B22:G22) -> 0 | I22: 2025
A23: x(STL,2025) | B23: 0 | C23: 0 | D23: 0 | E23: 0 | F23: 0 | G23: 0 | H23: =SUM(B23:G23) -> 0 | I23: 2025
A24: x(ATL,2025) | B24: 0 | C24: 0 | D24: 0 | E24: 0 | F24: 0 | G24: 0 | H24: =SUM(B24:G24) -> 0 | I24: 2025
A25: x(PHL,2025) | B25: 0 | C25: 0 | D25: 0 | E25: 0 | F25: 0 | G25: 0 | H25: =SUM(B25:G25) -> 0 | I25: 2025
A26: x(SEA,2026) | B26: 259200 | C26: 162000 | D26: 129600 | E26: 103450 | F26: 0 | G26: 0 | H26: =SUM(B26:G26) -> 654250 | I26: 2026
A27: x(DEN,2026) | B27: 0 | C27: 0 | D27: 0 | E27: 0 | F27: 0 | G27: 0 | H27: =SUM(B27:G27) -> 0 | I27: 2026
A28: x(STL,2026) | B28: 0 | C28: 0 | D28: 0 | E28: 74750 | F28: 283500 | G28: 141750 | H28: =SUM(B28:G28) -> 500000 | I28: 2026
A29: x(ATL,2026) | B29: 0 | C29: 0 | D29: 0 | E29: 0 | F29: 0 | G29: 0 | H29: =SUM(B29:G29) -> 0 | I29: 2026
A30: x(PHL,2026) | B30: 0 | C30: 0 | D30: 0 | E30: 0 | F30: 0 | G30: 0 | H30: =SUM(B30:G30) -> 0 | I30: 2026
A31: x(SEA,2027) | B31: 466560 | C31: 291600 | D31: 0 | E31: 0 | F31: 0 | G31: 0 | H31: =SUM(B31:G31) -> 758160 | I31: 2027
A32: x(DEN,2027) | B32: 0 | C32: 0 | D32: 0 | E32: 0 | F32: 0 | G32: 0 | H32: =SUM(B32:G32) -> 0 | I32: 2027
... A35: x(PHL,2027) | B35: 0 | C35: 0 | D35: 0 | E35: 0 | F35: 0 | G35: 0 | H35: =SUM(B35:G35) -> 0 | I35: 2027
A38: Tranfer ? (z(w,t)) | B38: 2025 | C38: 2026 | D38: 2027
A39: y(SEA,S) | B39: 0 | C39: 0 | D39: 0
A40: y(SEA,L) | B40: 0 | C40: 0 | D40: 0
A41: y(DEN,S) | B41: 0 | C41: 0 | D41: 0
A42: y(DEN,L) | B42: 0 | C42: 0 | D42: 0
A43: y(STL,S) | B43: 1 | C43: 0 | D43: 1
A44: y(STL,L) | B44: 0 | C44: 0 | D44: 0
A45: y(ATL,S) | B45: 0 | C45: 0 | D45: 0
A46: y(ATL,L) | B46: 0 | C46: 0 | D46: 0
A47: y(PHL,S) | B47: 0 | C47: 0 | D47: 0
A48: y(PHL,L) | B48: 0 | C48: 0 | D48: 0
...

Sheet Q6_insourcing
A1: SportB – MIP Model: Insourcing
A4: SECTION 1 – DECISION VARIABLES
A5: y(w,s,t) = 1 if warehouse w is open at size s (S=small, L=large) in year t [Binary]
A6: Variable y(w,s,t) | B6: 2024 | C6: 2025 | D6: 2026 | E6: 2027
A7: y(SEA,S) | B7: 0 | C7: 0 | D7: 0 | E7: 0
A8: y(SEA,L) | B8: 0 | C8: 0 | D8: 0 | E8: 0
A9: y(DEN,S) | B9: 0 | C9: 0 | D9: 1 | E9: 0
A10: y(DEN,L) | B10: 0 | C10: 0 | D10: 0 | E10: 1
A11: y(STL,S) | B11: 1 | C11: 0 | D11: 0 | E11: 0
A12: y(STL,L) | B12: 0 | C12: 1 | D12: 1 | E12: 1
A13: y(ATL,S) | B13: 0 | C13: 0 | D13: 0 | E13: 1
A14: y(ATL,L) | B14: 0 | C14: 0 | D14: 0 | E14: 0
A15: y(PHL,S) | B15: 0 | C15: 0 | D15: 0 | E15: 0
A16: y(PHL,L) | B16: 0 | C16: 0 | D16: 0 | E16: 0
A19: x(w,reg,t) = # orders shipped from warehouse w to region reg in year t [Continuous ≥ 0]
A20: x(w,reg) → | B20: West | C20: Southw | D20: Northw | E20: Midwes | F20: Northe | G20: Southe | H20: Total orders | I20: Year
A21: x(SEA,2025) | B21: 0 | C21: 0 | D21: 0 | E21: 0 | F21: 0 | G21: 0 | H21: =SUM(B21:G21) -> 0 | I21: 2025
A22: x(DEN,2025) | B22: 0 | C22: 0 | D22: 0 | E22: 0 | F22: 0 | G22: 0 | H22: =SUM(B22:G22) -> 0 | I22: 2025
A23: x(STL,2025) | B23: 144000 | C23: 90000 | D23: 72000 | E23: 99000 | F23: 157500 | G23: 78750 | H23: =SUM(B23:G23) -> 641250 | I23: 2025
A24: x(ATL,2025) | B24: 0 | C24: 0 | D24: 0 | E24: 0 | F24: 0 | G24: 0 | H24: =SUM(B24:G24) -> 0 | I24: 2025
A25: x(PHL,2025) | B25: 0 | C25: 0 | D25: 0 | E25: 0 | F25: 0 | G25: 0 | H25: =SUM(B25:G25) -> 0 | I25: 2025
A26: x(SEA,2026) | B26: 0 | C26: 0 | D26: 0 | E26: 0 | F26: 0 | G26: 0 | H26: =SUM(B26:G26) -> 0 | I26: 2026
A27: x(DEN,2026) | B27: 259200 | C27: 162000 | D27: 0 | E27: 0 | F27: 0 | G27: 0 | H27: =SUM(B27:G27) -> 421200 | I27: 2026
A28: x(STL,2026) | B28: 0 | C28: 0 | D28: 129600 | E28: 178200 | F28: 283500 | G28: 141750 | H28: =SUM(B28:G28) -> 733050 | I28: 2026
A29: x(ATL,2026) | B29: 0 | C29: 0 | D29: 0 | E29: 0 | F29: 0 | G29: 0 | H29: =SUM(B29:G29) -> 0 | I29: 2026
A30: x(PHL,2026) | B30: 0 | C30: 0 | D30: 0 | E30: 0 | F30: 0 | G30: 0 | H30: =SUM(B30:G30) -> 0 | I30: 2026
A31: x(SEA,2027) | B31: 0 | C31: 0 | D31: 0 | E31: 0 | F31: 0 | G31: 0 | H31: =SUM(B31:G31) -> 0 | I31: 2027
A32: x(DEN,2027) | B32: 466560 | C32: 291600 | D32: 64340 | E32: 0 | F32: 0 | G32: 0 | H32: =SUM(B32:G32) -> 822500 | I32: 2027
... A35: x(PHL,2027) | B35: 0 | C35: 0 | D35: 0 | E35: 0 | F35: 0 | G35: 0 | H35: =SUM(B35:G35) -> 0 | I35: 2027
A38: Tranfer ? | B38: 2025 | C38: 2026 | D38: 2027
A39: y(SEA,S) | B39: 0 | C39: 0 | D39: 0
A40: y(SEA,L) | B40: 0 | C40: 0 | D40: 0
A41: y(DEN,S) | B41: 0 | C41: 0 | D41: 1
A42: y(DEN,L) | B42: 0 | C42: 0 | D42: 0
A43: y(STL,S) | B43: 1 | C43: 0 | D43: 0
A44: y(STL,L) | B44: 0 | C44: 0 | D44: 0
A45: y(ATL,S) | B45: 0 | C45: 0 | D45: 0
A46: y(ATL,L) | B46: 0 | C46: 0 | D46: 0
A47: y(PHL,S) | B47: 0 | C47: 0 | D47: 0
A48: y(PHL,L) | B48: 0 | C48: 0 | D48: 0
...
